Captured traceback
Traceback (most recent call last):
  File "e:\data\python\preventista\preventista.py", line 62, in select_client
    self.dialog = Select_client(callback)
  File "e:\data\python\preventista\dialogs\select_client.py", line 46, in __init__
    self.clientes = import_dsv(r"e:\python\data\input\clientes.csv")
  File "e:\data\python\preventista\auto_dsv.py", line 7, in import_dsv
    data = open(filename).read()
IOError: [Errno 2] No such file or directory: 'e:\\python\\data\\input\\clientes.csv'
